Workbook

Sheet ´Master
A1: key | B1: model | C1: project | D1: question | E1: AA_v1 | F1: NA_v1 | G1: LLM1_v1 | H1: LLM2_v1 | I1: AA_v2 | J1: NA_v2 | K1: LLM1_v2 | L1: LLM2_v2 | M1: AA_v3 | N1: NA_v3 | O1: LLM1_v3 | P1: LLM2_v3 | Q1: AA_v4 | R1: NA_v4 | S1: LLM1_v4 | T1: LLM2_v4 | U1: AA_v5 | V1: NA_v5 | W1: LLM1_v5 | X1: LLM2_v5
A2: qwen3_US285851_Q28 | B2: =VLOOKUP(A2,'v1'!A:B,2,FALSE) -> qwen3 | C2: =VLOOKUP(A2,'v1'!A:C,3,FALSE) -> US285851 | D2: =VLOOKUP(RIGHT(A2,3),Questions!A:C,3,FALSE) -> 4 | E2: =VLOOKUP(A2,'v1'!A:G,7,FALSE) -> 1 | F2: =VLOOKUP(A2,'v1'!A:H,8,FALSE) -> 1 | G2: =VLOOKUP(A2,'GPT4-judge1'!A:G,6,FALSE) -> 3 | H2: =VLOOKUP(A2,GP5_judge1!A:F,6,FALSE) -> 3 | I2: =VLOOKUP(A2,'v2'!A:H,7,FALSE) -> 3 | J2: =VLOOKUP(A2,'v2'!A:H,8,FALSE) -> 1 | K2: =VLOOKUP(A2,GP4_judge2!A:F,6,FALSE) -> 3 | L2: =VLOOKUP(A2,GP5_judge2!A:F,6,FALSE) -> 3 | M2: =VLOOKUP(A2,'v3'!A:H,7,FALSE) -> 2 | N2: =VLOOKUP(A2,'v3'!A:H,8,FALSE) -> 2 | O2: =VLOOKUP(A2,GP4_judge3!A:F,6,FALSE) -> 3 | P2: =VLOOKUP(A2,GP5_judge3!A:F,6,FALSE) -> 3 | Q2: =VLOOKUP(A2,'v4'!A:H,7,FALSE) -> 3 | R2: =VLOOKUP(A2,'v4'!A:H,8,FALSE) -> 3 | S2: =VLOOKUP(A2,GP4_judge4!A:F,6,FALSE) -> 3 | T2: =VLOOKUP(A2,'GP5-judge4'!A:F,6,FALSE) -> 3 | U2: =VLOOKUP(A2,'v5'!A:H,7,FALSE) -> 0 | V2: =VLOOKUP(A2,'v5'!A:H,8,FALSE) -> 3 | W2: =VLOOKUP(A2,GP4_judge5!A:F,6,FALSE) -> 3 | X2: =VLOOKUP(A2,GP5_judge5!A:F,6,FALSE) -> 3
A3: qwen3_US285851_Q29 | B3: =VLOOKUP(A3,'v1'!A:B,2,FALSE) -> qwen3 | C3: =VLOOKUP(A3,'v1'!A:C,3,FALSE) -> US285851 | D3: =VLOOKUP(RIGHT(A3,3),Questions!A:C,3,FALSE) -> 5 | E3: =VLOOKUP(A3,'v1'!A:G,7,FALSE) -> 1 | F3: =VLOOKUP(A3,'v1'!A:H,8,FALSE) -> 1 | G3: =VLOOKUP(A3,'GPT4-judge1'!A:G,6,FALSE) -> 3 | H3: =VLOOKUP(A3,GP5_judge1!A:F,6,FALSE) -> 3 | I3: =VLOOKUP(A3,'v2'!A:H,7,FALSE) -> 3 | J3: =VLOOKUP(A3,'v2'!A:H,8,FALSE) -> 1 | K3: =VLOOKUP(A3,GP4_judge2!A:F,6,FALSE) -> 3 | L3: =VLOOKUP(A3,GP5_judge2!A:F,6,FALSE) -> 3 | M3: =VLOOKUP(A3,'v3'!A:H,7,FALSE) -> 0 | N3: =VLOOKUP(A3,'v3'!A:H,8,FALSE) -> 1 | O3: =VLOOKUP(A3,GP4_judge3!A:F,6,FALSE) -> 3 | P3: =VLOOKUP(A3,GP5_judge3!A:F,6,FALSE) -> 3 | Q3: =VLOOKUP(A3,'v4'!A:H,7,FALSE) -> 2 | R3: =VLOOKUP(A3,'v4'!A:H,8,FALSE) -> 1 | S3: =VLOOKUP(A3,GP4_judge4!A:F,6,FALSE) -> 3 | T3: =VLOOKUP(A3,'GP5-judge4'!A:F,6,FALSE) -> 3 | U3: =VLOOKUP(A3,'v5'!A:H,7,FALSE) -> 1 | V3: =VLOOKUP(A3,'v5'!A:H,8,FALSE) -> 0 | W3: =VLOOKUP(A3,GP4_judge5!A:F,6,FALSE) -> 3 | X3: =VLOOKUP(A3,GP5_judge5!A:F,6,FALSE) -> 3
A4: qwen3_US285851_Q30 | B4: =VLOOKUP(A4,'v1'!A:B,2,FALSE) -> qwen3 | C4: =VLOOKUP(A4,'v1'!A:C,3,FALSE) -> US285851 | D4: =VLOOKUP(RIGHT(A4,3),Questions!A:C,3,FALSE) -> 2 | E4: =VLOOKUP(A4,'v1'!A:G,7,FALSE) -> 0 | F4: =VLOOKUP(A4,'v1'!A:H,8,FALSE) -> 1 | G4: =VLOOKUP(A4,'GPT4-judge1'!A:G,6,FALSE) -> 3 | H4: =VLOOKUP(A4,GP5_judge1!A:F,6,FALSE) -> 2 | I4: =VLOOKUP(A4,'v2'!A:H,7,FALSE) -> 0 | J4: =VLOOKUP(A4,'v2'!A:H,8,FALSE) -> 1 | K4: =VLOOKUP(A4,GP4_judge2!A:F,6,FALSE) -> 3 | L4: =VLOOKUP(A4,GP5_judge2!A:F,6,FALSE) -> 2 | M4: =VLOOKUP(A4,'v3'!A:H,7,FALSE) -> 0 | N4: =VLOOKUP(A4,'v3'!A:H,8,FALSE) -> 0 | O4: =VLOOKUP(A4,GP4_judge3!A:F,6,FALSE) -> 3 | P4: =VLOOKUP(A4,GP5_judge3!A:F,6,FALSE) -> 2 | Q4: =VLOOKUP(A4,'v4'!A:H,7,FALSE) -> 0 | R4: =VLOOKUP(A4,'v4'!A:H,8,FALSE) -> 0 | S4: =VLOOKUP(A4,GP4_judge4!A:F,6,FALSE) -> 3 | T4: =VLOOKUP(A4,'GP5-judge4'!A:F,6,FALSE) -> 2 | U4: =VLOOKUP(A4,'v5'!A:H,7,FALSE) -> 0 | V4: =VLOOKUP(A4,'v5'!A:H,8,FALSE) -> 1 | W4: =VLOOKUP(A4,GP4_judge5!A:F,6,FALSE) -> 3 | X4: =VLOOKUP(A4,GP5_judge5!A:F,6,FALSE) -> 2
A5: qwen3_US285851_Q31 | B5: =VLOOKUP(A5,'v1'!A:B,2,FALSE) -> qwen3 | C5: =VLOOKUP(A5,'v1'!A:C,3,FALSE) -> US285851 | D5: =VLOOKUP(RIGHT(A5,3),Questions!A:C,3,FALSE) -> 6 | E5: =VLOOKUP(A5,'v1'!A:G,7,FALSE) -> 0 | F5: =VLOOKUP(A5,'v1'!A:H,8,FALSE) -> 1 | G5: =VLOOKUP(A5,'GPT4-judge1'!A:G,6,FALSE) -> 3 | H5: =VLOOKUP(A5,GP5_judge1!A:F,6,FALSE) -> 3 | I5: =VLOOKUP(A5,'v2'!A:H,7,FALSE) -> 1 | J5: =VLOOKUP(A5,'v2'!A:H,8,FALSE) -> 1 | K5: =VLOOKUP(A5,GP4_judge2!A:F,6,FALSE) -> 3 | L5: =VLOOKUP(A5,GP5_judge2!A:F,6,FALSE) -> 3 | M5: =VLOOKUP(A5,'v3'!A:H,7,FALSE) -> 1 | N5: =VLOOKUP(A5,'v3'!A:H,8,FALSE) -> 1 | O5: =VLOOKUP(A5,GP4_judge3!A:F,6,FALSE) -> 3 | P5: =VLOOKUP(A5,GP5_judge3!A:F,6,FALSE) -> 3 | Q5: =VLOOKUP(A5,'v4'!A:H,7,FALSE) -> 0 | R5: =VLOOKUP(A5,'v4'!A:H,8,FALSE) -> 1 | S5: =VLOOKUP(A5,GP4_judge4!A:F,6,FALSE) -> 3 | T5: =VLOOKUP(A5,'GP5-judge4'!A:F,6,FALSE) -> 3 | U5: =VLOOKUP(A5,'v5'!A:H,7,FALSE) -> 1 | V5: =VLOOKUP(A5,'v5'!A:H,8,FALSE) -> 0 | W5: =VLOOKUP(A5,GP4_judge5!A:F,6,FALSE) -> 3 | X5: =VLOOKUP(A5,GP5_judge5!A:F,6,FALSE) -> 3
A6: qwen3_US285851_Q32 | B6: =VLOOKUP(A6,'v1'!A:B,2,FALSE) -> qwen3 | C6: =VLOOKUP(A6,'v1'!A:C,3,FALSE) -> US285851 | D6: =VLOOKUP(RIGHT(A6,3),Questions!A:C,3,FALSE) -> 1 | E6: =VLOOKUP(A6,'v1'!A:G,7,FALSE) -> 0 | F6: =VLOOKUP(A6,'v1'!A:H,8,FALSE) -> 0 | G6: =VLOOKUP(A6,'GPT4-judge1'!A:G,6,FALSE) -> 3 | H6: =VLOOKUP(A6,GP5_judge1!A:F,6,FALSE) -> 3 | I6: =VLOOKUP(A6,'v2'!A:H,7,FALSE) -> 0 | J6: =VLOOKUP(A6,'v2'!A:H,8,FALSE) -> 0 | K6: =VLOOKUP(A6,GP4_judge2!A:F,6,FALSE) -> 3 | L6: =VLOOKUP(A6,GP5_judge2!A:F,6,FALSE) -> 3 | M6: =VLOOKUP(A6,'v3'!A:H,7,FALSE) -> 0 | N6: =VLOOKUP(A6,'v3'!A:H,8,FALSE) -> 0 | O6: =VLOOKUP(A6,GP4_judge3!A:F,6,FALSE) -> 3 | P6: =VLOOKUP(A6,GP5_judge3!A:F,6,FALSE) -> 3 | Q6: =VLOOKUP(A6,'v4'!A:H,7,FALSE) -> 0 | R6: =VLOOKUP(A6,'v4'!A:H,8,FALSE) -> 0 | S6: =VLOOKUP(A6,GP4_judge4!A:F,6,FALSE) -> 3 | T6: =VLOOKUP(A6,'GP5-judge4'!A:F,6,FALSE) -> 3 | U6: =VLOOKUP(A6,'v5'!A:H,7,FALSE) -> 1 | V6: =VLOOKUP(A6,'v5'!A:H,8,FALSE) -> 2 | W6: =VLOOKUP(A6,GP4_judge5!A:F,6,FALSE) -> 3 | X6: =VLOOKUP(A6,GP5_judge5!A:F,6,FALSE) -> 3
A7: qwen3_US285851_Q33 | B7: =VLOOKUP(A7,'v1'!A:B,2,FALSE) -> qwen3 | C7: =VLOOKUP(A7,'v1'!A:C,3,FALSE) -> US285851 | D7: =VLOOKUP(RIGHT(A7,3),Questions!A:C,3,FALSE) -> 8 | E7: =VLOOKUP(A7,'v1'!A:G,7,FALSE) -> 1 | F7: =VLOOKUP(A7,'v1'!A:H,8,FALSE) -> 1 | G7: =VLOOKUP(A7,'GPT4-judge1'!A:G,6,FALSE) -> 3 | H7: =VLOOKUP(A7,GP5_judge1!A:F,6,FALSE) -> 3 | I7: =VLOOKUP(A7,'v2'!A:H,7,FALSE) -> 2 | J7: =VLOOKUP(A7,'v2'!A:H,8,FALSE) -> 1 | K7: =VLOOKUP(A7,GP4_judge2!A:F,6,FALSE) -> 3 | L7: =VLOOKUP(A7,GP5_judge2!A:F,6,FALSE) -> 3 | M7: =VLOOKUP(A7,'v3'!A:H,7,FALSE) -> 1 | N7: =VLOOKUP(A7,'v3'!A:H,8,FALSE) -> 1 | O7: =VLOOKUP(A7,GP4_judge3!A:F,6,FALSE) -> 3 | P7: =VLOOKUP(A7,GP5_judge3!A:F,6,FALSE) -> 3 | Q7: =VLOOKUP(A7,'v4'!A:H,7,FALSE) -> 2 | R7: =VLOOKUP(A7,'v4'!A:H,8,FALSE) -> 2 | S7: =VLOOKUP(A7,GP4_judge4!A:F,6,FALSE) -> 3 | T7: =VLOOKUP(A7,'GP5-judge4'!A:F,6,FALSE) -> 3 | U7: =VLOOKUP(A7,'v5'!A:H,7,FALSE) -> 2 | V7: =VLOOKUP(A7,'v5'!A:H,8,FALSE) -> 2 | W7: =VLOOKUP(A7,GP4_judge5!A:F,6,FALSE) -> 3 | X7: =VLOOKUP(A7,GP5_judge5!A:F,6,FALSE) -> 3
A8: qwen3_US285851_Q34 | B8: =VLOOKUP(A8,'v1'!A:B,2,FALSE) -> qwen3 | C8: =VLOOKUP(A8,'v1'!A:C,3,FALSE) -> US285851 | D8: =VLOOKUP(RIGHT(A8,3),Questions!A:C,3,FALSE) -> 3 | E8: =VLOOKUP(A8,'v1'!A:G,7,FALSE) -> 1 | F8: =VLOOKUP(A8,'v1'!A:H,8,FALSE) -> 1 | G8: =VLOOKUP(A8,'GPT4-judge1'!A:G,6,FALSE) -> 3 | H8: =VLOOKUP(A8,GP5_judge1!A:F,6,FALSE) -> 3 | I8: =VLOOKUP(A8,'v2'!A:H,7,FALSE) -> 2 | J8: =VLOOKUP(A8,'v2'!A:H,8,FALSE) -> 2 | K8: =VLOOKUP(A8,GP4_judge2!A:F,6,FALSE) -> 3 | L8: =VLOOKUP(A8,GP5_judge2!A:F,6,FALSE) -> 3 | M8: =VLOOKUP(A8,'v3'!A:H,7,FALSE) -> 0 | N8: =VLOOKUP(A8,'v3'!A:H,8,FALSE) -> 0 | O8: =VLOOKUP(A8,GP4_judge3!A:F,6,FALSE) -> 3 | P8: =VLOOKUP(A8,GP5_judge3!A:F,6,FALSE) -> 3 | Q8: =VLOOKUP(A8,'v4'!A:H,7,FALSE) -> 0 | R8: =VLOOKUP(A8,'v4'!A:H,8,FALSE) -> 0 | S8: =VLOOKUP(A8,GP4_judge4!A:F,6,FALSE) -> 3 | T8: =VLOOKUP(A8,'GP5-judge4'!A:F,6,FALSE) -> 3 | U8: =VLOOKUP(A8,'v5'!A:H,7,FALSE) -> 0 | V8: =VLOOKUP(A8,'v5'!A:H,8,FALSE) -> 0 | W8: =VLOOKUP(A8,GP4_judge5!A:F,6,FALSE) -> 3 | X8: =VLOOKUP(A8,GP5_judge5!A:F,6,FALSE) -> 3
A9: qwen3_US285851_Q35 | B9: =VLOOKUP(A9,'v1'!A:B,2,FALSE) -> qwen3 | C9: =VLOOKUP(A9,'v1'!A:C,3,FALSE) -> US285851 | D9: =VLOOKUP(RIGHT(A9,3),Questions!A:C,3,FALSE) -> 10 | E9: =VLOOKUP(A9,'v1'!A:G,7,FALSE) -> 2 | F9: =VLOOKUP(A9,'v1'!A:H,8,FALSE) -> 2 | G9: =VLOOKUP(A9,'GPT4-judge1'!A:G,6,FALSE) -> 3 | H9: =VLOOKUP(A9,GP5_judge1!A:F,6,FALSE) -> 3 | I9: =VLOOKUP(A9,'v2'!A:H,7,FALSE) -> 1 | J9: =VLOOKUP(A9,'v2'!A:H,8,FALSE) -> 1 | K9: =VLOOKUP(A9,GP4_judge2!A:F,6,FALSE) -> 3 | L9: =VLOOKUP(A9,GP5_judge2!A:F,6,FALSE) -> 3 | M9: =VLOOKUP(A9,'v3'!A:H,7,FALSE) -> 2 | N9: =VLOOKUP(A9,'v3'!A:H,8,FALSE) -> 1 | O9: =VLOOKUP(A9,GP4_judge3!A:F,6,FALSE) -> 3 | P9: =VLOOKUP(A9,GP5_judge3!A:F,6,FALSE) -> 3 | Q9: =VLOOKUP(A9,'v4'!A:H,7,FALSE) -> 2 | R9: =VLOOKUP(A9,'v4'!A:H,8,FALSE) -> 2 | S9: =VLOOKUP(A9,GP4_judge4!A:F,6,FALSE) -> 3 | T9: =VLOOKUP(A9,'GP5-judge4'!A:F,6,FALSE) -> 3 | U9: =VLOOKUP(A9,'v5'!A:H,7,FALSE) -> 2 | V9: =VLOOKUP(A9,'v5'!A:H,8,FALSE) -> 3 | W9: =VLOOKUP(A9,GP4_judge5!A:F,6,FALSE) -> 3 | X9: =VLOOKUP(A9,GP5_judge5!A:F,6,FALSE) -> 3
A10: qwen3_US285851_Q36 | B10: =VLOOKUP(A10,'v1'!A:B,2,FALSE) -> qwen3 | C10: =VLOOKUP(A10,'v1'!A:C,3,FALSE) -> US285851 | D10: =VLOOKUP(RIGHT(A10,3),Questions!A:C,3,FALSE) -> 9 | E10: =VLOOKUP(A10,'v1'!A:G,7,FALSE) -> 1 | F10: =VLOOKUP(A10,'v1'!A:H,8,FALSE) -> 1 | G10: =VLOOKUP(A10,'GPT4-judge1'!A:G,6,FALSE) -> 3 | H10: =VLOOKUP(A10,GP5_judge1!A:F,6,FALSE) -> 3 | I10: =VLOOKUP(A10,'v2'!A:H,7,FALSE) -> 1 | J10: =VLOOKUP(A10,'v2'!A:H,8,FALSE) -> 1 | K10: =VLOOKUP(A10,GP4_judge2!A:F,6,FALSE) -> 3 | L10: =VLOOKUP(A10,GP5_judge2!A:F,6,FALSE) -> 3 | M10: =VLOOKUP(A10,'v3'!A:H,7,FALSE) -> 2 | N10: =VLOOKUP(A10,'v3'!A:H,8,FALSE) -> 1 | O10: =VLOOKUP(A10,GP4_judge3!A:F,6,FALSE) -> 3 | P10: =VLOOKUP(A10,GP5_judge3!A:F,6,FALSE) -> 3 | Q10: =VLOOKUP(A10,'v4'!A:H,7,FALSE) -> 1 | R10: =VLOOKUP(A10,'v4'!A:H,8,FALSE) -> 2 | S10: =VLOOKUP(A10,GP4_judge4!A:F,6,FALSE) -> 3 | T10: =VLOOKUP(A10,'GP5-judge4'!A:F,6,FALSE) -> 3 | U10: =VLOOKUP(A10,'v5'!A:H,7,FALSE) -> 2 | V10: =VLOOKUP(A10,'v5'!A:H,8,FALSE) -> 2 | W10: =VLOOKUP(A10,GP4_judge5!A:F,6,FALSE) -> 3 | X10: =VLOOKUP(A10,GP5_judge5!A:F,6,FALSE) -> 3
A11: qwen3_US285851_Q37 | B11: =VLOOKUP(A11,'v1'!A:B,2,FALSE) -> qwen3 | C11: =VLOOKUP(A11,'v1'!A:C,3,FALSE) -> US285851 | D11: =VLOOKUP(RIGHT(A11,3),Questions!A:C,3,FALSE) -> 7 | E11: =VLOOKUP(A11,'v1'!A:G,7,FALSE) -> 2 | F11: =VLOOKUP(A11,'v1'!A:H,8,FALSE) -> 1 | G11: =VLOOKUP(A11,'GPT4-judge1'!A:G,6,FALSE) -> 3 | H11: =VLOOKUP(A11,GP5_judge1!A:F,6,FALSE) -> 3 | I11: =VLOOKUP(A11,'v2'!A:H,7,FALSE) -> 3 | J11: =VLOOKUP(A11,'v2'!A:H,8,FALSE) -> 1 | K11: =VLOOKUP(A11,GP4_judge2!A:F,6,FALSE) -> 3 | L11: =VLOOKUP(A11,GP5_judge2!A:F,6,FALSE) -> 3 | M11: =VLOOKUP(A11,'v3'!A:H,7,FALSE) -> 2 | N11: =VLOOKUP(A11,'v3'!A:H,8,FALSE) -> 1 | O11: =VLOOKUP(A11,GP4_judge3!A:F,6,FALSE) -> 3 | P11: =VLOOKUP(A11,GP5_judge3!A:F,6,FALSE) -> 3 | Q11: =VLOOKUP(A11,'v4'!A:H,7,FALSE) -> 2 | R11: =VLOOKUP(A11,'v4'!A:H,8,FALSE) -> 2 | S11: =VLOOKUP(A11,GP4_judge4!A:F,6,FALSE) -> 3 | T11: =VLOOKUP(A11,'GP5-judge4'!A:F,6,FALSE) -> 3 | U11: =VLOOKUP(A11,'v5'!A:H,7,FALSE) -> 2 | V11: =VLOOKUP(A11,'v5'!A:H,8,FALSE) -> 3 | W11: =VLOOKUP(A11,GP4_judge5!A:F,6,FALSE) -> 3 | X11: =VLOOKUP(A11,GP5_judge5!A:F,6,FALSE) -> 3
A12: qwen3_US293949_Q38 | B12: =VLOOKUP(A12,'v1'!A:B,2,FALSE) -> qwen3 | C12: =VLOOKUP(A12,'v1'!A:C,3,FALSE) -> US293949 | D12: =VLOOKUP(RIGHT(A12,3),Questions!A:C,3,FALSE) -> 4 | E12: =VLOOKUP(A12,'v1'!A:G,7,FALSE) -> 2 | F12: =VLOOKUP(A12,'v1'!A:H,8,FALSE) -> 1 | G12: =VLOOKUP(A12,'GPT4-judge1'!A:G,6,FALSE) -> 3 | H12: =VLOOKUP(A12,GP5_judge1!A:F,6,FALSE) -> 3 | I12: =VLOOKUP(A12,'v2'!A:H,7,FALSE) -> 2 | J12: =VLOOKUP(A12,'v2'!A:H,8,FALSE) -> 1 | K12: =VLOOKUP(A12,GP4_judge2!A:F,6,FALSE) -> 3 | L12: =VLOOKUP(A12,GP5_judge2!A:F,6,FALSE) -> 3 | M12: =VLOOKUP(A12,'v3'!A:H,7,FALSE) -> 0 | N12: =VLOOKUP(A12,'v3'!A:H,8,FALSE) -> 0 | O12: =VLOOKUP(A12,GP4_judge3!A:F,6,FALSE) -> 3 | P12: =VLOOKUP(A12,GP5_judge3!A:F,6,FALSE) -> 3 | Q12: =VLOOKUP(A12,'v4'!A:H,7,FALSE) -> 0 | R12: =VLOOKUP(A12,'v4'!A:H,8,FALSE) -> 0 | S12: =VLOOKUP(A12,GP4_judge4!A:F,6,FALSE) -> 3 | T12: =VLOOKUP(A12,'GP5-judge4'!A:F,6,FALSE) -> 2 | U12: =VLOOKUP(A12,'v5'!A:H,7,FALSE) -> 0 | V12: =VLOOKUP(A12,'v5'!A:H,8,FALSE) -> 2 | W12: =VLOOKUP(A12,GP4_judge5!A:F,6,FALSE) -> 2 | X12: =VLOOKUP(A12,GP5_judge5!A:F,6,FALSE) -> 3
A13: qwen3_US293949_Q39 | B13: =VLOOKUP(A13,'v1'!A:B,2,FALSE) -> qwen3 | C13: =VLOOKUP(A13,'v1'!A:C,3,FALSE) -> US293949 | D13: =VLOOKUP(RIGHT(A13,3),Questions!A:C,3,FALSE) -> 5 | E13: =VLOOKUP(A13,'v1'!A:G,7,FALSE) -> 0 | F13: =VLOOKUP(A13,'v1'!A:H,8,FALSE) -> 0 | G13: =VLOOKUP(A13,'GPT4-judge1'!A:G,6,FALSE) -> 3 | H13: =VLOOKUP(A13,GP5_judge1!A:F,6,FALSE) -> 3 | I13: =VLOOKUP(A13,'v2'!A:H,7,FALSE) -> 0 | J13: =VLOOKUP(A13,'v2'!A:H,8,FALSE) -> 1 | K13: =VLOOKUP(A13,GP4_judge2!A:F,6,FALSE) -> 3 | L13: =VLOOKUP(A13,GP5_judge2!A:F,6,FALSE) -> 3 | M13: =VLOOKUP(A13,'v3'!A:H,7,FALSE) -> 0 | N13: =VLOOKUP(A13,'v3'!A:H,8,FALSE) -> 1 | O13: =VLOOKUP(A13,GP4_judge3!A:F,6,FALSE) -> 3 | P13: =VLOOKUP(A13,GP5_judge3!A:F,6,FALSE) -> 3 | Q13: =VLOOKUP(A13,'v4'!A:H,7,FALSE) -> 2 | R13: =VLOOKUP(A13,'v4'!A:H,8,FALSE) -> 1 | S13: =VLOOKUP(A13,GP4_judge4!A:F,6,FALSE) -> 3 | T13: =VLOOKUP(A13,'GP5-judge4'!A:F,6,FALSE) -> 3 | U13: =VLOOKUP(A13,'v5'!A:H,7,FALSE) -> 1 | V13: =VLOOKUP(A13,'v5'!A:H,8,FALSE) -> 0 | W13: =VLOOKUP(A13,GP4_judge5!A:F,6,FALSE) -> 3 | X13: =VLOOKUP(A13,GP5_judge5!A:F,6,FALSE) -> 3
... A201: deepseek-r1_US285851_Q35 | B201: =VLOOKUP(A201,'v1'!A:B,2,FALSE) -> deepseek-r1 | C201: =VLOOKUP(A201,'v1'!A:C,3,FALSE) -> US285851 | D201: =VLOOKUP(RIGHT(A201,3),Questions!A:C,3,FALSE) -> 10 | E201: =VLOOKUP(A201,'v1'!A:G,7,FALSE) -> 1 | F201: =VLOOKUP(A201,'v1'!A:H,8,FALSE) -> 1 | G201: =VLOOKUP(A201,'GPT4-judge1'!A:G,6,FALSE) -> 3 | H201: =VLOOKUP(A201,GP5_judge1!A:F,6,FALSE) -> 3 | I201: =VLOOKUP(A201,'v2'!A:H,7,FALSE) -> 2 | J201: =VLOOKUP(A201,'v2'!A:H,8,FALSE) -> 3 | K201: =VLOOKUP(A201,GP4_judge2!A:F,6,FALSE) -> 2 | L201: =VLOOKUP(A201,GP5_judge2!A:F,6,FALSE) -> 3 | M201: =VLOOKUP(A201,'v3'!A:H,7,FALSE) -> #N/A | N201: =VLOOKUP(A201,'v3'!A:H,8,FALSE) -> #N/A | O201: =VLOOKUP(A201,GP4_judge3!A:F,6,FALSE) -> #N/A | P201: =VLOOKUP(A201,GP5_judge3!A:F,6,FALSE) -> #N/A | Q201: =VLOOKUP(A201,'v4'!A:H,7,FALSE) -> #N/A | R201: =VLOOKUP(A201,'v4'!A:H,8,FALSE) -> #N/A | S201: =VLOOKUP(A201,GP4_judge4!A:F,6,FALSE) -> #N/A | T201: =VLOOKUP(A201,'GP5-judge4'!A:F,6,FALSE) -> #N/A | U201: =VLOOKUP(A201,'v5'!A:H,7,FALSE) -> #N/A | V201: =VLOOKUP(A201,'v5'!A:H,8,FALSE) -> #N/A | W201: =VLOOKUP(A201,GP4_judge5!A:F,6,FALSE) -> #N/A | X201: =VLOOKUP(A201,GP5_judge5!A:F,6,FALSE) -> #N/A

Sheet GP5_judge1
A1: Master Key | B1: model | C1: projectID | D1: questionID | E1: answer | F1: Grade
A2: =_xlfn.CONCAT(C2,"_",D2) -> llama3.2_US285851_Q28 | B2: gpt-5-chat-latest | C2: llama3.2_US285851 | D2: Q28 | E2: **2** – The conclusion is logically structured and acknowledges the lack of budget and timing compliance data, leading to a reasonable, cautious answer (“uncertain whether completed on time and within budget”). It correctly identifies missing information as a limiting factor and gives a sensible recommendation. However, it does not explicitly reference any concrete evidence from the timeline (such as total project span or delays) to strengthen the assessment, which keeps it from the highest score. | F2: =RIGHT(LEFT(E2,3),1) -> 2
A3: =_xlfn.CONCAT(C3,"_",D3) -> llama3.2_US285851_Q29 | B3: gpt-5-chat-latest | C3: llama3.2_US285851 | D3: Q29 | E3: **2** **Explanation:** The answer shows some understanding of the project plan and correctly points out unusual entries (e.g., zeroday tasks) and potentially long activities that could cause delays. It also identifies possible structural issues like unclear milestones or dependencies. However, the analysis remains somewhat general and speculative — it doesn’t clearly identify where actual delays occurred or connect them directly to the project timeline. The causes presented (“lack of assignment,” “external dependencies”) are reasonable hypotheses but lack concrete evidence from the provided data. Overall, it demonstrates partial insight (above minimal comprehension) but falls short of a detailed, wellsupported explanation — thus merits a **2** on the 0–3 scale. | F3: =RIGHT(LEFT(E3,3),1) -> 2
A4: =_xlfn.CONCAT(C4,"_",D4) -> llama3.2_US285851_Q30 | B4: gpt-5-chat-latest | C4: llama3.2_US285851 | D4: Q30 | E4: **2** The final conclusions provide a generally sound, moderately detailed assessment. The answer clearly notes that there were deviations in timeline and resource allocation and acknowledges the lack of contextual data needed for a full evaluation. It shows reasonable understanding of the event log and logical reasoning about adherence to plan and objectives. However, it does not offer strong evidence directly connected to specific data points or timelines in the log (e.g., identifying the *Confirmar/garantir fonte orçamentária* 55day duration as a likely bottleneck) and remains somewhat generic. The reasoning is correct but not deeply datadriven or conclusive. Overall, the answer demonstrates fair analytical quality — better than superficial (so not a “1”), but short of a fully wellsubstantiated analysis (so not a “3”). | F4: =RIGHT(LEFT(E4,3),1) -> 2
A5: =_xlfn.CONCAT(C5,"_",D5) -> llama3.2_US285851_Q31 | B5: gpt-5-chat-latest | C5: llama3.2_US285851 | D5: Q31 | E5: **Grade: 2** **Explanation:** The final part of the answer reasonably addresses the question based on the available data. It correctly observes that the event log does not explicitly mention issues or obstacles, and it identifies potentially long-duration tasks as possible indicators of challenges. The response also suggests what additional information would be needed for a more complete assessment, showing understanding of project risk and issue management concepts. However, it lacks a direct evaluation or synthesis — for instance, it doesn’t explicitly state whether the long tasks reflect actual issues or normal project steps, nor does it propose conclusions about how issues were managed. The response remains somewhat generic and exploratory rather than conclusive, which makes it solid but not fully complete. | F5: 2
A6: =_xlfn.CONCAT(C6,"_",D6) -> llama3.2_US285851_Q32 | B6: gpt-5-chat-latest | C6: llama3.2_US285851 | D6: Q32 | E6: **2** The final conclusions of the answer are relevant and generally accurate — the respondent correctly notes that the provided project plan doesn’t include sufficient information to definitively assess whether the project stayed within allocated resources. The answer acknowledges gaps in data (human, financial, technical) and provides reasonable recommendations for further analysis. However, it stops short of offering a clear, direct conclusion (e.g., “No, we cannot determine resource adherence based on available data”) and is somewhat generic in its recommendations. Thus, it demonstrates good understanding but lacks precise closure and specific linkage to the given project log—earning a **2 out of 3**. | F6: =RIGHT(LEFT(E6,3),1) -> 2
A7: =_xlfn.CONCAT(C7,"_",D7) -> llama3.2_US285851_Q33 | B7: gpt-5-chat-latest | C7: llama3.2_US285851 | D7: Q33 | E7: **3** The final conclusions are well structured, relevant, and directly address systemic improvement areas in project execution. The answer identifies specific and actionable enhancements—scope clarity, risk management, sequencing, communication, and overlap reduction—which are all grounded in standard project management best practices. The reasoning is coherent and aligns with the issues observable in the provided event log (e.g., long idle periods, overlapping or redundant tasks). Overall, this is a strong, well-reasoned answer deserving the maximum grade. | F7: =RIGHT(LEFT(E7,3),1) -> 3
A8: =_xlfn.CONCAT(C8,"_",D8) -> llama3.2_US285851_Q34 | B8: gpt-5-chat-latest | C8: llama3.2_US285851 | D8: Q34 | E8: **2** The final conclusion is coherent and cautious: it acknowledges the available data and logically infers that milestones *seem* to have been met, given no explicit evidence of delay. However, it remains largely generic, reiterating the lack of milestone tracking data instead of offering a concrete or well-substantiated assessment based on the provided log. - **Strengths:** Reasonable logic; clear acknowledgment of data limitations; consistent reasoning. - **Weaknesses:** Too generic; lacks direct reference to key events or long-duration tasks as potential delays (e.g., “Confirmar/garantir fonte orçamentária” lasting 55 days); does not explicitly confirm or refute milestone achievement based on project end alignment. Overall, it shows understanding but not a thorough evaluation — deserving a **2/3**. | F8: =RIGHT(LEFT(E8,3),1) -> 2
A9: =_xlfn.CONCAT(C9,"_",D9) -> llama3.2_US285851_Q35 | B9: gpt-5-chat-latest | C9: llama3.2_US285851 | D9: Q35 | E9: **3** The final recommendations are coherent, actionable, and directly relevant to the issues visible in the project log (e.g., vague roles, lack of risk mitigation, unclear milestones). They demonstrate a good understanding of project management best practices, addressing structure, stakeholder engagement, and continuous monitoring. The answer is comprehensive and well-organized, making it a strong and complete response worthy of the maximum grade. | F9: =RIGHT(LEFT(E9,3),1) -> 3
A10: =_xlfn.CONCAT(C10,"_",D10) -> llama3.2_US285851_Q36 | B10: gpt-5-chat-latest | C10: llama3.2_US285851 | D10: Q36 | E10: **3** The final conclusions are clear, accurate, and well-grounded in the project plan. The response identifies both positive aspects (clear scope definition, monitoring, communication, and change control) and a key improvement point (risk of scope creep). It demonstrates understanding of scope management lessons learned and ties them to specific project events. The reasoning is coherent and appropriately balanced, showing full comprehension of project scope management principles. | F10: =RIGHT(LEFT(E10,3),1) -> 3
A11: =_xlfn.CONCAT(C11,"_",D11) -> llama3.2_US285851_Q37 | B11: gpt-5-chat-latest | C11: llama3.2_US285851 | D11: Q37 | E11: **3** The final conclusions are comprehensive, clearly structured, and highly relevant to the event log provided. The advice addresses multiple key project management dimensions — planning, communication, risk management, progress tracking, adaptability, quality assurance, and role clarity — all of which are directly applicable to future similar projects. The points are actionable and demonstrate a strong understanding of project execution challenges. Overall, this is a complete and well-justified response deserving the highest grade on the 0–3 scale. | F11: =RIGHT(LEFT(E11,3),1) -> 3
A12: =_xlfn.CONCAT(C12,"_",D12) -> llama3.2_US293949_Q38 | B12: gpt-5-chat-latest | C12: llama3.2_US293949 | D12: Q38 | E12: **2** **Reasoning:** The final conclusion correctly recognizes the limited information available (no explicit budget or baseline deadlines) and appropriately avoids making unsupported claims. It identifies relevant timeline concerns and examples from the log, showing reasonable analytical thinking. However, it remains somewhat generic and inconclusive—it doesn’t synthesize findings into a clear final judgment about timeliness or performance relative to expectations. The answer is accurate and cautious but lacks depth or decisive evaluation expected for a top score. | F12: =RIGHT(LEFT(E12,3),1) -> 2
A13: =_xlfn.CONCAT(C13,"_",D13) -> llama3.2_US293949_Q39 | B13: gpt-5-chat-latest | C13: llama3.2_US293949 | D13: Q39 | E13: **2** **Justification:** The final conclusions correctly observe that no explicit delays are described in the event log and provide plausible general causes for potential delays (resource constraints, insufficient time allocation, etc.). The answer also acknowledges task overlaps and dependencies that might suggest risk areas. However, the analysis is relatively generic: it doesn’t clearly point to concrete evidence of delays visible in the event data (for example, unusually long durations like the 30day postimplementation activity or extended “Certificação da Implantação” tasks). As a result, while logically coherent and relevant, it lacks precision and depth in connecting findings directly to the dataset. | F13: =RIGHT(LEFT(E13,3),1) -> 2
A14: =_xlfn.CONCAT(C14,"_",D14) -> llama3.2_US293949_Q40 | B14: gpt-5-chat-latest | C14: llama3.2_US293949 | D14: Q40 | E14: **2** The conclusion provides a coherent assessment based on the available evidence, identifying partial adherence to the original plan, mentioning delays and revisions, and recognizing progress where appropriate. However, it remains somewhat generic and lacks strong linkage to specific project objectives or a clear quantitative evaluation of adherence. It demonstrates a reasonable but not comprehensive understanding — solid reasoning but not fully thorough or precise — deserving a **2 (good but not excellent)** on a 0–3 scale. | F14: =RIGHT(LEFT(E14,3),1) -> 2
A15: =_xlfn.CONCAT(C15,"_",D15) -> llama3.2_US293949_Q41 | B15: gpt-5-chat-latest | C15: llama3.2_US293949 | D15: Q41 | E15: **2** **Explanation:** The final conclusions demonstrate a reasonable understanding of the project plan and identify potential areas that might indicate issues (especially the long-duration tasks). The answer correctly notes the lack of contextual data and avoids unfounded claims. However, it doesn’t clearly state that unexpected issues were observed — it only hypothesizes what could indicate them. The discussion remains general rather than providing a concrete assessment of how obstacles were managed. Hence, while factually cautious and relevant, it lacks the depth or specificity needed for a top score. | F15: =RIGHT(LEFT(E15,3),1) -> 2
A16: =_xlfn.CONCAT(C16,"_",D16) -> llama3.2_US293949_Q42 | B16: gpt-5-chat-latest | C16: llama3.2_US293949 | D16: Q42 | E16: **2** **Justification:** The conclusion portion of the answer is coherent, structured, and correctly identifies that the project lacks sufficient budgetary data to confirm financial control, notes possible humanresource overloads, and finds technical resources apparently adequate. These points address the question reasonably and are supported by the event log characteristics. However, it remains somewhat generic and assumes rather than demonstrates whether the project *did* stay within allocated resources. The analysis stops at identifying uncertainties instead of giving a definitive evidencebased assessment. Hence it is above average in relevance and clarity but not fully conclusive — deserving a **2** rather than the maximum **3**. | F16: =RIGHT(LEFT(E16,3),1) -> 2
A17: =_xlfn.CONCAT(C17,"_",D17) -> llama3.2_US293949_Q43 | B17: gpt-5-chat-latest | C17: llama3.2_US293949 | D17: Q43 | E17: **3** — The answer is wellstructured, clear, and demonstrates a solid understanding of project management best practices. It identifies several realistic improvement areas (prioritization, timelines, risk management, reviews, communication) and links them to their potential positive impacts on project outcomes. The suggestions are concrete, relevant to the provided event log, and balanced with a recognition of missing context. Overall, it meets all the criteria for a highquality, complete conclusion deserving the maximum grade. | F17: =RIGHT(LEFT(E17,3),1) -> 3
... A21: =_xlfn.CONCAT(C21,"_",D21) -> llama3.2_US293949_Q47 | B21: gpt-5-chat-latest | C21: llama3.2_US293949 | D21: Q47 | E21: **3** The final conclusions are clear, structured, and wellaligned with the project data and the prompt’s goal (advice for future teams). The points provided are concrete, relevant to project management best practices, and directly connected to observed issues—such as timing, dependencies, and coordination. The recommendations are actionable and comprehensive, without being generic filler. Overall, this is a complete and highquality final answer deserving the maximum grade. | F21: =RIGHT(LEFT(E21,3),1) -> 3
A22: =_xlfn.CONCAT(C22,"_",D22) -> llama3.2_US37581_285851_293949_Q48 | B22: gpt-5-chat-latest | C22: llama3.2_US37581_285851_293949 | D22: Q48 | E22: 3 – The final conclusion is accurate and well justified. It correctly identifies that the data provided (event log of tasks, dates, and durations) does not include any explicit indicators of schedule adherence or budget consumption, and therefore it is not possible to determine whether the projects were completed on time or within budget. The reasoning is sound and the conclusion is appropriate given the available information. | F22: 3
A23: =_xlfn.CONCAT(C23,"_",D23) -> llama3.2_US37581_285851_293949_Q49 | B23: gpt-5-chat-latest | C23: llama3.2_US37581_285851_293949 | D23: Q49 | E23: **Grade: 1** **Rationale:** The answer does make a minimal attempt to identify possible delays by referencing specific activity IDs (e.g., AR 41, AR 42–44). However, it misreads parts of the data — the event logs clearly include both start and finish dates for every task, so saying “no completion date mentioned” or “expected completion dates are not mentioned” is inaccurate. It also fails to identify genuine performance bottlenecks visible in the data (e.g., very long tasks like “Confirmar/garantir fonte orçamentária — 55 days,” or “Acompanhar as atividades pós implantação — 22–30 days”). No meaningful analysis of causes is provided beyond generic statements. Overall, the conclusions are incomplete and not well grounded in the given dataset. | F23: 1
A24: =_xlfn.CONCAT(C24,"_",D24) -> llama3.2_US37581_285851_293949_Q50 | B24: gpt-5-chat-latest | C24: llama3.2_US37581_285851_293949 | D24: Q50 | E24: **2** The conclusion is reasonably clear and balanced. It recognizes both achievements (objectives largely met, many tasks completed) and issues (delays, weak dependencies, resource constraints). The assessment roughly corresponds to a “moderate adherence” interpretation. However, it stays general and lacks direct evidence from the event log to substantiate claims (e.g., examples of delayed tasks or timeline deviation), so it does not demonstrate strong analytical grounding. Therefore, it merits a **2/3** — solid but not fully evidencebased or precise. | F24: =RIGHT(LEFT(E24,3),1) -> 2
A25: =_xlfn.CONCAT(C25,"_",D25) -> llama3.2_US37581_285851_293949_Q51 | B25: gpt-5-chat-latest | C25: llama3.2_US37581_285851_293949 | D25: Q51 | E25: **2** The conclusion provides a reasonable, coherent answer — it identifies that no explicit issues appear in the plans, then infers possible management and governance gaps (change, risk, contingency, and communication). It’s logically sound, consistent with the prompt, and supports the evaluation with practical improvement suggestions. However, it doesn’t extract concrete examples from the event logs (e.g., long task durations or delays as evidence of issues), which limits the specificity of the analysis. The response shows understanding and interpretation but lacks direct data-based justification, thus meriting a solid but not top score. | F25: =RIGHT(LEFT(E25,3),1) -> 2
A26: =_xlfn.CONCAT(C26,"_",D26) -> llama3.2_US37581_285851_293949_Q52 | B26: gpt-5-chat-latest | C26: llama3.2_US37581_285851_293949 | D26: Q52 | E26: **1** The conclusion correctly acknowledges that insufficient data prevents a definitive assessment of whether the projects stayed within the allocated human, financial, and technical resources. However, it remains largely generic and speculative, with no evidence-based analysis or reference to the event log data. While it recognizes the data limitations (which is accurate), it doesn’t extract or infer any meaningful insight from the available project information. Thus, it shows minimal analytical contribution beyond pointing out missing information — deserving a low but not zero score. | F26: =RIGHT(LEFT(E26,3),1) -> 1
A27: =_xlfn.CONCAT(C27,"_",D27) -> llama3.2_US37581_285851_293949_Q53 | B27: gpt-5-chat-latest | C27: llama3.2_US37581_285851_293949 | D27: Q53 | E27: **3** The final conclusions are well structured, comprehensive, and directly address realistic improvement areas grounded in standard project management best practices. The points are clear, actionable, and relevant to the scenario described (timeline management, dependencies, updates, resource allocation, risk management, QA, and stakeholder communication). There are no apparent factual or logical gaps. It demonstrates a complete understanding of how to improve project outcomes. | F27: =RIGHT(LEFT(E27,3),1) -> 3
A28: =_xlfn.CONCAT(C28,"_",D28) -> llama3.2_US37581_285851_293949_Q54 | B28: gpt-5-chat-latest | C28: llama3.2_US37581_285851_293949 | D28: Q54 | E28: **Grade: 1** **Justification:** The final answer correctly acknowledges that there isn’t enough information to conclusively determine whether all milestones were achieved as planned. While this is a reasonable and factually coherent conclusion given the data, the response does not explicitly address the question using the event log provided or demonstrate any analysis of milestone completion within the available evidence. It remains generic and procedural rather than evaluative. Thus, it shows partial understanding and minimal application of available data — earning a **1 (below average but not incorrect)** on the 0–3 scale. | F28: 1
A29: =_xlfn.CONCAT(C29,"_",D29) -> llama3.2_US37581_285851_293949_Q55 | B29: gpt-5-chat-latest | C29: llama3.2_US37581_285851_293949 | D29: Q55 | E29: **3** The final recommendations are clear, structured, and actionable. They address key aspects of project management — milestones and timelines, resource allocation, dependencies, plan updates, frameworks, accountability, and tools — all of which are relevant given the event log data and the patterns of task delays and coordination complexity. The answer demonstrates good synthesis of lessons learned from the projects and translates them into practical guidance for future initiatives. | F29: =RIGHT(LEFT(E29,3),1) -> 3
A30: =_xlfn.CONCAT(C30,"_",D30) -> llama3.2_US37581_285851_293949_Q56 | B30: gpt-5-chat-latest | C30: llama3.2_US37581_285851_293949 | D30: Q56 | E30: **3** The final conclusions are clear, wellstructured, and directly address lessons learned in project scope management. They identify realistic scheduling, resource allocation, task validation, dependency planning, and clear scope definition — all key aspects of effective scope management. The observations align with issues visible in the event log and translate them into actionable lessons. The reasoning is coherent and complete, so this deserves the maximum score. | F30: =RIGHT(LEFT(E30,3),1) -> 3
A31: =_xlfn.CONCAT(C31,"_",D31) -> llama3.2_US37581_285851_293949_Q57 | B31: gpt-5-chat-latest | C31: llama3.2_US37581_285851_293949 | D31: Q57 | E31: **3** The final conclusions are comprehensive, relevant, and well structured. The advice directly addresses project management best practices such as goal clarity, timeline realism, risk management, stakeholder communication, contingency planning, phased delivery, monitoring progress, quality assurance, defining roles, and incorporating lessons learned. These recommendations are general but meaningful and clearly rooted in common issues visible in the provided project logs (delays, unclear responsibilities, long task durations). Overall, it demonstrates a strong understanding and provides actionable guidance — deserving the maximum score. | F31: =RIGHT(LEFT(E31,3),1) -> 3
A32: =_xlfn.CONCAT(C32,"_",D32) -> llama3.2_US37581_Q18 | B32: gpt-5-chat-latest | C32: llama3.2_US37581 | D32: Q18 | E32: **2** The final conclusion appropriately recognizes that the event log does not include data about actual completion status or costs, and that therefore one cannot determine definitively whether the project was on time or within budget. That is correct and relevant. However, the answer drifts into speculation (“likely completed on time,” “could indicate efficient resource allocation”), which weakens the analytical precision. It shows basic understanding and partial justification but relies on conjecture rather than evidence — thus it deserves a *2* on the 0–3 scale. | F32: =RIGHT(LEFT(E32,3),1) -> 2
A33: =_xlfn.CONCAT(C33,"_",D33) -> llama3.2_US37581_Q19 | B33: gpt-5-chat-latest | C33: llama3.2_US37581 | D33: Q19 | E33: **2** The final conclusions of the answer are **accurate in a general sense** — they correctly note the lack of explicit baseline timelines and identify typical causes of delay (resource constraints, dependencies, complexity). The reasoning is **methodologically sound** and acknowledges the limitation of the available data. However, the answer does **not engage directly with the event log** to identify where delays might actually have occurred (e.g., long gaps between tasks, long durations such as the 10-day “Montar DSOL” or the 22-day “Acompanhar atividades pós-implantação”). It remains **too generic** and avoids specific observations that the data could support. Thus, the answer shows partial understanding (sound logic but weak application to the dataset), meriting a **grade of 2 out of 3**. | F33: =RIGHT(LEFT(E33,3),1) -> 2
A34: =_xlfn.CONCAT(C34,"_",D34) -> llama3.2_US37581_Q20 | B34: gpt-5-chat-latest | C34: llama3.2_US37581 | D34: Q20 | E34: **2** **Explanation:** The final conclusions are coherent and moderately supported by the data provided. The answer reasonably infers that the project adhered to the plan overall, acknowledging minor delays and data limitations. It shows a fair understanding of schedule adherence and task completion. However, it lacks deeper analysis of the evident longer tasks (e.g., “Montar DSOL”, “Certificação da Implantação”, “Acompanhar atividades pós-implantação”) and does not connect these delays explicitly to performance or adherence issues. The reasoning is sound but somewhat generic and does not fully leverage the detailed event log. | F34: =RIGHT(LEFT(E34,3),1) -> 2
A35: =_xlfn.CONCAT(C35,"_",D35) -> llama3.2_US37581_Q21 | B35: gpt-5-chat-latest | C35: llama3.2_US37581 | D35: Q21 | E35: **2** – The answer demonstrates a reasonable understanding of the question and offers plausible inferences about potential issues and how they might have been managed. While it correctly acknowledges that there’s no explicit mention of unexpected problems in the event log, it goes beyond that by identifying plausible risk areas (backup, monitoring) and proposing appropriate management strategies (change management, reviews, contingency plans). However, it relies heavily on speculation rather than evidence from the provided data, so it lacks the depth or direct linkage to concrete events needed for the highest score. | F35: =RIGHT(LEFT(E35,3),1) -> 2
A36: =_xlfn.CONCAT(C36,"_",D36) -> llama3.2_US37581_Q22 | B36: gpt-5-chat-latest | C36: llama3.2_US37581 | D36: Q22 | E36: **Grade: 1** **Reasoning:** The final part of the answer correctly recognizes that the available data (event log/project plan) does not contain explicit information about *resource allocation* in human, financial, or technical terms, and therefore a definitive conclusion cannot be drawn. This acknowledgement is valid and demonstrates some understanding of the task’s constraints. However, it falls short in the following ways: - It does **not provide any concrete evaluation** or inference based on the data that *is* available (e.g., consistency of task durations, absence of overlapping assignments suggesting resource strain, or possible indicators of staying within bounds). - The answer remains **generic and exploratory**, focusing on what should be analyzed rather than drawing a conclusion relevant to the question. - There is no synthesis of observed evidence or final judgment (e.g., “insufficient data to conclude, but no signs of resource overuse are evident”). Thus, while methodologically correct in its caution, it offers limited evaluative value and minimal insight—warranting a low but nonzero score. | F36: 1
A37: =_xlfn.CONCAT(C37,"_",D37) -> llama3.2_US37581_Q23 | B37: gpt-5-chat-latest | C37: llama3.2_US37581 | D37: Q23 | E37: **3** The final conclusions are clear, structured, and strongly aligned with best practices in project management. The answer identifies multiple actionable improvement areas — timeline precision, dependency mapping, detailed task breakdown, monitoring, risk management, stakeholder communication, and contingency planning. Each point is relevant to the provided project plan and logically tied to improving performance and outcomes. The recommendations show a solid understanding of project dynamics and are expressed concisely and effectively. | F37: =RIGHT(LEFT(E37,3),1) -> 3
A38: =_xlfn.CONCAT(C38,"_",D38) -> llama3.2_US37581_Q24 | B38: gpt-5-chat-latest | C38: llama3.2_US37581 | D38: Q24 | E38: **2** The final conclusions are partially correct — the answer recognizes that not all milestones appear to have been achieved as planned and points out timeline inconsistencies and delays. However, it remains vague and does not reference specific milestones or evidence from the event log to support the claim. The reasoning is general and speculative rather than data-driven. It shows moderate understanding but lacks concrete verification or precise analysis, which keeps it from a top score. | F38: =RIGHT(LEFT(E38,3),1) -> 2
A39: =_xlfn.CONCAT(C39,"_",D39) -> llama3.2_US37581_Q25 | B39: gpt-5-chat-latest | C39: llama3.2_US37581 | D39: Q25 | E39: **3** The answer gives a clear, wellstructured, and relevant set of recommendations that directly address potential improvements for future projects. It covers key aspects such as acceptance criteria, plan adjustments, QA emphasis, standardization, communication, and adds thoughtful bestpractice suggestions (agile, PM tools, change management). The advice is actionable and coherent with the context of the project plan. Overall, it fully meets the expectations for a strong, comprehensive conclusion. | F39: =RIGHT(LEFT(E39,3),1) -> 3
A40: =_xlfn.CONCAT(C40,"_",D40) -> llama3.2_US37581_Q26 | B40: gpt-5-chat-latest | C40: llama3.2_US37581 | D40: Q26 | E40: **3** The final conclusions clearly identify concrete and relevant lessons about project scope management, such as scope creep, unclear boundaries, lack of testing, and insufficient documentation. The improvement suggestions directly address these issues with actionable recommendations (better scope definition, review, prioritization, testing, documentation). The response demonstrates solid understanding and logical connection to the project context, meeting the maximum criteria for completeness and relevance. | F40: =RIGHT(LEFT(E40,3),1) -> 3
A41: =_xlfn.CONCAT(C41,"_",D41) -> llama3.2_US37581_Q27 | B41: gpt-5-chat-latest | C41: llama3.2_US37581 | D41: Q27 | E41: **3** The final conclusions are clear, structured, and practical. The advice addresses key project management dimensions—planning, change management, testing, communication, postimplementation followup, and technical debt—each linked logically to observable issues in the log. The recommendations are actionable and framed in a way that future teams can realistically apply. Overall, it demonstrates a comprehensive understanding of project improvement based on the provided experience. | F41: =RIGHT(LEFT(E41,3),1) -> 3
A42: =_xlfn.CONCAT(C42,"_",D42) -> gpt-4o_US285851_Q28 | B42: gpt-5-chat-latest | C42: gpt-4o_US285851 | D42: Q28 | E42: **3** The conclusion is accurate, wellreasoned, and clearly justified given the available data. It correctly notes that the event log does not contain baseline schedule or budget information, so a definitive answer cannot be given. It also highlights observed longduration tasks that *could* indicate delays, while avoiding unwarranted assumptions. The response is complete, precise, and appropriately cautious—fully meeting expectations for this type of analysis. | F42: =RIGHT(LEFT(E42,3),1) -> 3
A43: =_xlfn.CONCAT(C43,"_",D43) -> gpt-4o_US285851_Q29 | B43: gpt-5-chat-latest | C43: gpt-4o_US285851 | D43: Q29 | E43: **3** The final conclusions accurately identify the main delay ("Confirmar/garantir fonte orçamentária" – 55 days) and correctly interpret it as a bottleneck likely related to budget approval or coordination issues. It also distinguishes between genuinely delayed tasks and those that are long but expected (e.g., postimplementation monitoring). The reasoning is wellaligned with the data and demonstrates good understanding of project analysis. | F43: =RIGHT(LEFT(E43,3),1) -> 3
...

Sheet GP5_judge2
A1: Master Key | B1: model | C1: projectID | D1: questionID | E1: answer | F1: Grade
A2: =_xlfn.CONCAT(C2,"_",D2) -> llama3.2_US285851_Q28 | B2: gpt-5-chat-latest | C2: llama3.2_US285851 | D2: Q28 | E2: **3** The conclusion is clear, accurate, and directly addresses both elements of the question. It correctly notes that: - Most tasks were completed on time, but some (especially Task 5) took significantly longer, which may have affected the schedule. - The budget aspect cannot be evaluated because cost data are missing from the event log. The reasoning is aligned with the available evidence and avoids speculation beyond the data. It fully satisfies the evaluation criteria, so it deserves the maximum grade. | F2: =RIGHT(LEFT(E2,3),1) -> 3
A3: =_xlfn.CONCAT(C3,"_",D3) -> llama3.2_US285851_Q29 | B3: gpt-5-chat-latest | C3: llama3.2_US285851 | D3: Q29 | E3: **3** The conclusion accurately identifies the main delays (notably the 55day financing approval and 30day postimplementation followup), highlights repeated or overlapping tasks (CMDB updates, firewall activities), and reasonably infers causes such as duplication, coordination, and resource issues. It also provides coherent improvement suggestions. The response is wellfocused on project delays and causes, meeting the requirements for a top score. | F3: =RIGHT(LEFT(E3,3),1) -> 3
A4: =_xlfn.CONCAT(C4,"_",D4) -> llama3.2_US285851_Q30 | B4: gpt-5-chat-latest | C4: llama3.2_US285851 | D4: Q30 | E4: **Grade: 2** **Rationale:** The final conclusions summarize the project’s adherence moderately well: they correctly identify delays (notably Task5), duplication (Tasks29and39), and general adherence issues. The answer provides reasonable qualitative and quantitative judgments (“task efficiency60%,resourceutilization70%”) and practical improvement suggestions. However, it lacks stronger linkage between observed evidence and the overarching “original plan and objectives.” The numerical ratings appear arbitrary rather than clearly derived, and the analysis does not fully articulate whether the project met its intended functional or business outcomes. In short, it’s a fair, partially substantiated evaluation—better than minimal but not consistently rigorous. | F4: 2
A5: =_xlfn.CONCAT(C5,"_",D5) -> llama3.2_US285851_Q31 | B5: gpt-5-chat-latest | C5: llama3.2_US285851 | D5: Q31 | E5: **3** The answer provides a clear, coherent evaluation grounded in the event log. It identifies the main long-duration task (Task5) as a potential issue, notes possible rework or repetition, and explains that although there were delays, they were manageable and did not significantly disrupt the project. The conclusion directly addresses the question (“were there unexpected issues or obstacles, and how were they managed?”) and supports its claims with relevant observations from the data. Overall, the reasoning is complete and accurate, fitting the top mark on the 0–3 scale. | F5: =RIGHT(LEFT(E5,3),1) -> 3
A6: =_xlfn.CONCAT(C6,"_",D6) -> llama3.2_US285851_Q32 | B6: gpt-5-chat-latest | C6: llama3.2_US285851 | D6: Q32 | E6: **2** The conclusion is reasonably well supported and demonstrates some understanding of resource utilization (identifying long task durations and possible inefficiencies). It links those delays to potential human and financial resource issues while acknowledging the lack of full data for a definitive conclusion. However, it does not make a clear, direct statement answering whether the project *stayed within* allocated resources—it only suggests possible underutilization or inefficiency. The analysis is partially complete but not conclusive, hence a good but not top score. | F6: =RIGHT(LEFT(E6,3),1) -> 2
A7: =_xlfn.CONCAT(C7,"_",D7) -> llama3.2_US285851_Q33 | B7: gpt-5-chat-latest | C7: llama3.2_US285851 | D7: Q33 | E7: **3** The final conclusions are coherent, relevant, and well-aligned with the event log. They identify concrete improvement areas (task breakdown, dependency management, resource allocation, and monitoring) and propose reasonable corrective actions grounded in sound project management practices. The reasoning is consistent with the data provided and demonstrates understanding of where inefficiencies and bottlenecks occurred. | F7: =RIGHT(LEFT(E7,3),1) -> 3
A8: =_xlfn.CONCAT(C8,"_",D8) -> llama3.2_US285851_Q34 | B8: gpt-5-chat-latest | C8: llama3.2_US285851 | D8: Q34 | E8: **2** **Explanation:** The final conclusion correctly states that most project milestones were achieved as planned, while acknowledging some delays and duplicated or overlapping tasks. It demonstrates a reasonable understanding of the event log and identifies relevant evidence (e.g., duplicate tasks, unusual durations). However, it stops short of providing clear evidence that milestones were verified against a predetermined plan or specific milestone criteria. The reasoning is sound but lacks depth and precise linkage between findings and milestone achievement. Overall, the answer is **mostly correct and reasonable**, but not fully thorough — hence a **grade of 2 out of 3**. | F8: =RIGHT(LEFT(E8,3),1) -> 2
A9: =_xlfn.CONCAT(C9,"_",D9) -> llama3.2_US285851_Q35 | B9: gpt-5-chat-latest | C9: llama3.2_US285851 | D9: Q35 | E9: **3** The final recommendations are clear, structured, and directly address the issues identified in the event log. They propose practical measures—such as better use of project management tools, improved resource allocation, dependency management, and regular monitoring—to mitigate similar delays in future projects. The suggestions are comprehensive, cover both process and communication improvements, and demonstrate sound understanding of project management best practices. | F9: =RIGHT(LEFT(E9,3),1) -> 3
A10: =_xlfn.CONCAT(C10,"_",D10) -> llama3.2_US285851_Q36 | B10: gpt-5-chat-latest | C10: llama3.2_US285851 | D10: Q36 | E10: **3** The final conclusions effectively address lessons related to **project scope management** using clear evidence from the event log. The answer identifies repeated and overlapping tasks (Tasks17,39), points to unclear ownership and evolving requirements, and ties these to **scope creep, lack of clarity in deliverables, and poor communication**—all central to scope management lessons. It also notes anomalies (like zeroday validation) as indicators of weak task control and documentation. Overall, the response demonstrates solid understanding and specificity, fully meeting expectations for insight on scope definition and control. | F10: =RIGHT(LEFT(E10,3),1) -> 3
A11: =_xlfn.CONCAT(C11,"_",D11) -> llama3.2_US285851_Q37 | B11: gpt-5-chat-latest | C11: llama3.2_US285851 | D11: Q37 | E11: **3** – The answer provides a wellstructured, insightful, and evidencebased set of recommendations that directly reflect the event log issues. It correctly identifies the unusually long task duration as a bottleneck, notes duplicated resource effort, emphasizes communication improvement, suggests automation for repetitive activities, and recommends continuous plan review. These points are accurate, relevant, and actionable. The reasoning aligns clearly with information from the project log and demonstrates a thorough understanding of performance factors. | F11: =RIGHT(LEFT(E11,3),1) -> 3
A12: =_xlfn.CONCAT(C12,"_",D12) -> llama3.2_US293949_Q38 | B12: gpt-5-chat-latest | C12: llama3.2_US293949 | D12: Q38 | E12: **2** – The conclusion is mostly accurate and demonstrates reasonable understanding of the event log. It correctly notes that some tasks exceeded typical durations and highlights potential delays and inefficiencies. It also appropriately acknowledges the lack of sufficient data to make a definitive claim about schedule and budget compliance. However, it could be more concise and better structured in summarizing the findings. The reasoning is sound but not fully precise or datadriven enough to merit the highest grade. | F12: =RIGHT(LEFT(E12,3),1) -> 2
A13: =_xlfn.CONCAT(C13,"_",D13) -> llama3.2_US293949_Q39 | B13: gpt-5-chat-latest | C13: llama3.2_US293949 | D13: Q39 | E13: **3** The final conclusions are coherent, well-structured, and fully aligned with the prompt's objective. The answer correctly identifies delays, specifies which tasks were affected, and provides plausible, multifactor explanations — long durations, task repetition, dependencies, and resource constraints — all derived from the event log. The reasoning is comprehensive and accurate without major omissions or factual errors. | F13: =RIGHT(LEFT(E13,3),1) -> 3
A14: =_xlfn.CONCAT(C14,"_",D14) -> llama3.2_US293949_Q40 | B14: gpt-5-chat-latest | C14: llama3.2_US293949 | D14: Q40 | E14: **2** The final conclusion adequately summarizes the project’s adherence as “moderate,” noting both ontime and delayed tasks and identifying performance issues causing deviations. The reasoning is coherent and consistent with the event log’s data. However, it lacks clear quantitative benchmarks or deeper linkage to project objectives beyond timing, making it more descriptive than analytical. Thus, the answer is solid but not fully detailed or comprehensive—worthy of a **2/3**. | F14: =RIGHT(LEFT(E14,3),1) -> 2
A15: =_xlfn.CONCAT(C15,"_",D15) -> llama3.2_US293949_Q41 | B15: gpt-5-chat-latest | C15: llama3.2_US293949 | D15: Q41 | E15: **2** The answer correctly identifies key tasks with longer-than-expected durations (specifically the firewall-related tasks and reporting tasks) and plausibly interprets them as unexpected obstacles. It also suggests reasonable generic management responses (rescheduling, reallocating resources, stakeholder communication, troubleshooting). However, the explanation remains somewhat general and not fully grounded in the provided event log beyond noting delays, lacking any specific reference to concrete corrective actions or observed adaptations in the schedule. Therefore, it shows good but not excellent analytical connection between evidence and interpretation. | F15: =RIGHT(LEFT(E15,3),1) -> 2
A16: =_xlfn.CONCAT(C16,"_",D16) -> llama3.2_US293949_Q42 | B16: gpt-5-chat-latest | C16: llama3.2_US293949 | D16: Q42 | E16: **2** The final conclusion is coherent, cautious, and grounded in the data from the event log. It correctly notes that certain tasks (notably firewall rule implementation and postdeployment monitoring) took unusually long and could indicate stretched human or technical resources. It also appropriately highlights the lack of financial or budgetary data, so a definitive conclusion cannot be made. However, the answer remains somewhat general and qualitative—it identifies performance issues but does not explicitly connect them to concrete evidence of exceeding financial or human resource allocations. It could improve by synthesizing these observations into a clearer, more decisive judgment about whether the project stayed within or exceeded its resources. | F16: =RIGHT(LEFT(E16,3),1) -> 2
A17: =_xlfn.CONCAT(C17,"_",D17) -> llama3.2_US293949_Q43 | B17: gpt-5-chat-latest | C17: llama3.2_US293949 | D17: Q43 | E17: **3** The final conclusions are clear, relevant, and directly aligned with the event log evidence. The answer identifies concrete performance issues (firewall approval delays, long certification, postimplementation monitoring) and translates them into actionable improvement steps — addressing bottlenecks, dependencies, and parallelization. It also provides managerial recommendations (workflow optimization, agile methods) that logically follow from the analysis. The reasoning is coherent and comprehensive enough to merit the maximum score. | F17: =RIGHT(LEFT(E17,3),1) -> 3
A18: =_xlfn.CONCAT(C18,"_",D18) -> llama3.2_US293949_Q44 | B18: gpt-5-chat-latest | C18: llama3.2_US293949 | D18: Q44 | E18: **Grade: 2** **Reasoning:** The final conclusions correctly identify that some tasks show irregular durations (both unusually long and unusually short) and that these deviations could signal potential performance or planning issues. The answer appropriately acknowledges uncertainty and lack of context. However, the analysis includes some inaccuracies—for instance, there is no explicit evidence in the log that task #20 extended to July 6, and tasks largely appear to have been completed within the logged periods without clear “planned vs. actual” comparison data. The response also fails to directly address the main question (“Were all milestones achieved as planned?”) with a definitive yes/no conclusion. Overall, it shows a good understanding of issues in the data but lacks precision and direct alignment with the prompt’s requested conclusion—hence a midhigh score of **2**. | F18: 2
A19: =_xlfn.CONCAT(C19,"_",D19) -> llama3.2_US293949_Q45 | B19: gpt-5-chat-latest | C19: llama3.2_US293949 | D19: Q45 | E19: **3** The final conclusions are wellstructured, clear, and directly grounded in the evidence from the event log. The recommendations (identifying critical path activities, standardizing procedures, automating repetitive tasks, monitoring progress, and applying structured methodologies) are all relevant, specific, and actionable. They demonstrate strong understanding of both project management and process improvement. There are no major gaps or misinterpretations, so this deserves the maximum score. | F19: =RIGHT(LEFT(E19,3),1) -> 3
A20: =_xlfn.CONCAT(C20,"_",D20) -> llama3.2_US293949_Q46 | B20: gpt-5-chat-latest | C20: llama3.2_US293949 | D20: Q46 | E20: **3** The final conclusions clearly identify relevant lessons learned about project scope management based on evidence from the event log. The points about underestimated task scope, unclear expectations, and insufficient resource allocation directly relate to scope management challenges. The reasoning logically connects task durations with scope control issues, and the summary provides actionable insights for improvement. Overall, it is coherent, relevant, and complete, fully meeting the intent of the question. | F20: =RIGHT(LEFT(E20,3),1) -> 3
A21: =_xlfn.CONCAT(C21,"_",D21) -> llama3.2_US293949_Q47 | B21: gpt-5-chat-latest | C21: llama3.2_US293949 | D21: Q47 | E21: **3** The final conclusions provide a clear, structured, and relevant set of recommendations directly based on the event log data. The advice addresses multiple key aspects — performance issues, resource management, progress monitoring, quality assurance, automation, and communication. Each point is actionable and grounded in the context of the observed project execution. Overall, it demonstrates comprehensive understanding and sound reasoning, fully meeting the task's expectations. | F21: =RIGHT(LEFT(E21,3),1) -> 3
A22: =_xlfn.CONCAT(C22,"_",D22) -> llama3.2_US37581_285851_293949_Q48 | B22: gpt-5-chat-latest | C22: llama3.2_US37581_285851_293949 | D22: Q48 | E22: **2** The conclusion appropriately notes that the information provided is insufficient to determine whether deliverables were completed on time and within budget, acknowledging gaps in data (deadlines, budgets). The reasoning is cautious and factually sound, avoiding unsupported assumptions. However, it doesn’t make full or precise use of the event log to infer performance patterns or timing consistency between projects — it stays quite general. Thus, it demonstrates partial understanding and justified caution but lacks depth or specific analysis needed for a top score. | F22: =RIGHT(LEFT(E22,3),1) -> 2
